Traceback (most recent call last):
  File "/usr/share/miniconda/envs/how_to_eurec4a/lib/python3.8/site-packages/nbclient/client.py", line 730, in _async_poll_for_reply
    msg = await ensure_async(self.kc.shell_channel.get_msg(timeout=new_timeout))
  File "/usr/share/miniconda/envs/how_to_eurec4a/lib/python3.8/site-packages/nbclient/util.py", line 96, in ensure_async
    result = await obj
  File "/usr/share/miniconda/envs/how_to_eurec4a/lib/python3.8/site-packages/jupyter_client/asynchronous/channels.py", line 48, in get_msg
    raise Empty
_queue.Empty

During handling of the above exception, another exception occurred:

Traceback (most recent call last):
  File "/usr/share/miniconda/envs/how_to_eurec4a/lib/python3.8/site-packages/jupyter_cache/executors/utils.py", line 51, in single_nb_execution
    executenb(
  File "/usr/share/miniconda/envs/how_to_eurec4a/lib/python3.8/site-packages/nbclient/client.py", line 1204, in execute
    return NotebookClient(nb=nb, resources=resources, km=km, **kwargs).execute()
  File "/usr/share/miniconda/envs/how_to_eurec4a/lib/python3.8/site-packages/nbclient/util.py", line 84, in wrapped
    return just_run(coro(*args, **kwargs))
  File "/usr/share/miniconda/envs/how_to_eurec4a/lib/python3.8/site-packages/nbclient/util.py", line 62, in just_run
    return loop.run_until_complete(coro)
  File "/usr/share/miniconda/envs/how_to_eurec4a/lib/python3.8/asyncio/base_events.py", line 616, in run_until_complete
    return future.result()
  File "/usr/share/miniconda/envs/how_to_eurec4a/lib/python3.8/site-packages/nbclient/client.py", line 663, in async_execute
    await self.async_execute_cell(
  File "/usr/share/miniconda/envs/how_to_eurec4a/lib/python3.8/site-packages/nbclient/client.py", line 949, in async_execute_cell
    exec_reply = await self.task_poll_for_reply
  File "/usr/share/miniconda/envs/how_to_eurec4a/lib/python3.8/site-packages/nbclient/client.py", line 754, in _async_poll_for_reply
    await self._async_handle_timeout(timeout, cell)
  File "/usr/share/miniconda/envs/how_to_eurec4a/lib/python3.8/site-packages/nbclient/client.py", line 801, in _async_handle_timeout
    raise CellTimeoutError.error_from_timeout_and_cell(
nbclient.exceptions.CellTimeoutError: A cell timed out while it was being executed, after 90 seconds.
The message was: Cell execution timed out.
Here is a preview of the cell contents:
-------------------
['fig_height = len(datasets) * 0.5', 'fig, axs = plt.subplots(len(datasets), 1, figsize=(8, fig_height), sharex=True)', 'fig.set_constrained_layout(False)', "xfmt = dates.DateFormatter('%d.%m')", 'for d, dataset in enumerate(datasets):']
...
['    axs[d].set_ylabel(dataset.replace(".","\\n"), rotation=0, ha=\'right\')', '    axs[d].set(yticklabels=[])  # remove the tick labels', '    axs[d].tick_params(left=False)  # remove the ticks', 'axs[d].xaxis.set_major_formatter(xfmt)', 'plt.tight_layout()']
-------------------

